'book-10', 'XBT/USD']
'book-10', 'XBT/USD']
[320, {'b': [['33149.60000', '0.60100000', '1612137166.846375']], 'c': '971692050'}, 'book-10', 'XBT/USD']
[320, {'b': [['33153.20000', '3.26040738', '1612137166.847215']], 'c': '4054051317'}, 'book-10', 'XBT/USD']
[320, {'b': [['33153.20000', '3.27336574', '1612137167.248899']], 'c': '1532334467'}, 'book-10', 'XBT/USD']
[320, {'c': '1119147655', 'a': [['33168.30000', '0.77609026', '1612137167.280245']]}, 'book-10', 'XBT/USD']
[320, {'b': [['33153.20000', '3.56852574', '1612137167.281552']], 'c': '3286699058'}, 'book-10', 'XBT/USD']
[320, {'c': '515262153', 'a': [['33173.80000', '0.00000000', '1612137167.433760'], ['33174.30000', '2.26118255', '1612137166.389737', 'r']]}, 'book-10', 'XBT/USD']
[320, {'b': [['33150.10000', '0.15744000', '1612137167.439396']], 'c': '3909435288'}, 'book-10', 'XBT/USD']
[320, {'b': [['33153.20000', '3.81852574', '1612137167.454023']], 'c': '2202555572'}, 'book-10', 'XBT/USD']
[320, {'c': '4072552009', 'a': [['33171.00000', '0.50000000', '1612137167.507020']]}, 'book-10', 'XBT/USD']
[320, {'c': '4118257113', 'a': [['33174.30000', '0.00000000', '1612137167.507242'], ['33176.10000', '1.50725075', '1612137158.784406', 'r']]}, 'book-10', 'XBT/USD']
[320, {'b': [['33153.20000', '3.91852574', '1612137167.545091']], 'c': '1622177097'}, 'book-10', 'XBT/USD']
[320, {'b': [['33149.70000', '2.26051952', '1612137167.590527']], 'c': '4040736190'}, 'book-10', 'XBT/USD']
[320, {'b': [['33153.20000', '8.56852574', '1612137167.639129']], 'c': '748386771'}, 'book-10', 'XBT/USD']
[320, {'b': [['33153.20000', '8.31852574', '1612137167.789226']], 'c': '1458994184'}, 'book-10', 'XBT/USD']
[320, {'b': [['33153.20000', '3.66852574', '1612137167.989263']], 'c': '1785397747'}, 'book-10', 'XBT/USD']
[320, {'b': [['33153.20000', '3.76852574', '1612137168.005219']], 'c': '4289522019'}, 'book-10', 'XBT/USD']
[320, {'c': '2178967736', 'a': [['33168.30000', '0.00000000', '1612137168.022782'], ['33178.00000', '0.10000000', '1612137163.805726', 'r']]}, 'book-10', 'XBT/USD']
[320, {'c': '2827595954', 'a': [['33168.20000', '0.77609026', '1612137168.061627']]}, 'book-10', 'XBT/USD']
[320, {'c': '2178967736', 'a': [['33168.20000', '0.00000000', '1612137168.112891'], ['33178.00000', '0.10000000', '1612137163.805726', 'r']]}, 'book-10', 'XBT/USD']
[320, {'c': '1374051009', 'a': [['33168.10000', '0.77609026', '1612137168.150793']]}, 'book-10', 'XBT/USD']
[320, {'c': '2178967736', 'a': [['33168.10000', '0.00000000', '1612137168.186320'], ['33178.00000', '0.10000000', '1612137163.805726', 'r']]}, 'book-10', 'XBT/USD']
[320, {'c': '113443600', 'a': [['33168.00000', '0.77609026', '1612137168.223469']]}, 'book-10', 'XBT/USD']
[320, {'b': [['33153.20000', '3.86852574', '1612137168.227919']], 'c': '745522532'}, 'book-10', 'XBT/USD']
[320, {'b': [['33153.20000', '3.57336574', '1612137168.229440']], 'c': '1446814567'}, 'book-10', 'XBT/USD']
[320, {'c': '3508521167', 'a': [['33168.00000', '0.00000000', '1612137168.258893'], ['33178.00000', '0.10000000', '1612137163.805726', 'r']]}, 'book-10', 'XBT/USD']
[320, {'c': '3367341327', 'a': [['33168.30000', '0.18200000', '1612137168.371946']]}, 'book-10', 'XBT/USD']
[320, {'b': [['33153.20000', '3.32336574', '1612137168.395824']], 'c': '1134341444'}, 'book-10', 'XBT/USD']
[320, {'b': [['33150.10000', '0.00000000', '1612137168.415344'], ['33144.40000', '1.53891931', '1612137167.767334', 'r']], 'c': '2508911093'}, 'book-10', 'XBT/USD']
[320, {'b': [['33153.20000', '3.22336574', '1612137168.464904']], 'c': '1695589721'}, 'book-10', 'XBT/USD']
[320, {'b': [['33153.20000', '3.12336574', '1612137168.480683']], 'c': '2949603052'}, 'book-10', 'XBT/USD']
[320, {'c': '1057852838', 'a': [['33174.70000', '0.07920000', '1612137168.486979']]}, 'book-10', 'XBT/USD']
[320, {'b': [['33153.20000', '3.00336574', '1612137168.487657']], 'c': '1063849579'}, 'book-10', 'XBT/USD']
[320, {'c': '1127027695', 'a': [['33168.30000', '0.00000000', '1612137168.507094'], ['33176.10000', '1.50725075', '1612137158.784406', 'r']]}, 'book-10', 'XBT/USD']
[320, {'b': [['33153.20000', '2.90336574', '1612137168.564041']], 'c': '2234617520'}, 'book-10', 'XBT/USD']
[320, {'b': [['33153.20000', '2.80336574', '1612137168.565362']], 'c': '1974196764'}, 'book-10', 'XBT/USD']
[320, {'b': [['33153.20000', '0.80336574', '1612137168.639314']], 'c': '491842596'}, 'book-10', 'XBT/USD']
[320, {'b': [['33153.20000', '1.36211974', '1612137168.684746']], 'c': '1235008651'}, 'book-10', 'XBT/USD']
[320, {'b': [['33149.60000', '0.00000000', '1612137168.686202'], ['33140.70000', '0.00124380', '1612137148.941218', 'r']], 'c': '3044765644'}, 'book-10', 'XBT/USD']
[320, {'c': '90803034', 'a': [['33174.50000', '0.60291220', '1612137168.740929']]}, 'book-10', 'XBT/USD']
[320, {'c': '797420138', 'a': [['33170.00000', '1.20587531', '1612137168.756779']]}, 'book-10', 'XBT/USD']
[320, {'b': [['33153.20000', '3.36211974', '1612137168.758924']], 'c': '3749281035'}, 'book-10', 'XBT/USD']
[320, {'b': [['33153.20000', '3.26211974', '1612137168.764865']], 'c': '2816176067'}, 'book-10', 'XBT/USD']
[320, {'c': '2963286489', 'a': [['33168.30000', '0.28250000', '1612137168.778312']]}, 'book-10', 'XBT/USD']
[320, {'b': [['33149.60000', '0.59900000', '1612137168.808455']], 'c': '2560038530'}, 'book-10', 'XBT/USD']
[320, {'c': '3070566279', 'a': [['33168.30000', '0.00000000', '1612137168.831643'], ['33174.50000', '0.60291220', '1612137168.740929', 'r']]}, 'book-10', 'XBT/USD']
[320, {'c': '2861596789', 'a': [['33168.40000', '0.26008000', '1612137168.849224']]}, 'book-10', 'XBT/USD']
[320, {'a': [['36585.80000', '0.10682919', '1612329421.721169']]}, {'c': '4265541708', 'b': [['36586.40000', '0.00000000', '1612329421.721747'], ['36565.90000', '0.92955360', '1612329407.427657', 'r']]}, 'book-10', 'XBT/USD']
[320, {'c': '472229418', 'a': [['38665.60000', '0.00000000', '1612734158.860115'], ['38669.00000', '0.29793319', '1612734158.672640', 'r']]}, 'book-10', 'XBT/USD']
{'as': [['38655.10000', '0.01850000', '1612734157.975759'], ['38656.60000', '0.01850000', '1612734158.796481'], ['38656.70000', '0.01879392', '1612734158.850822'], ['38661.20000', '0.00872662', '1612734150.372700'], ['38662.00000', '0.02111625', '1612732217.220589'], ['38666.50000', '0.01000000', '1612734151.455692'], ['38667.30000', '0.00107048', '1612734158.042144'], ['38667.40000', '0.00200000', '1612734149.169895'], ['38667.50000', '0.00075189', '1612732623.687882'], ['38669.00000', '0.29793319', '1612734158.672640']], 'bs': [['38654.90000', '2.72330447', '1612734158.850916'], ['38654.80000', '0.51734813', '1612734157.105560'], ['38653.70000', '0.40000000', '1612734158.508245'], ['38653.60000', '1.03465690', '1612734156.120705'], ['38649.80000', '0.10206681', '1612734158.546761'], ['38649.70000', '0.51742108', '1612734149.112579'], ['38648.30000', '0.51400000', '1612734158.023113'], ['38648.10000', '0.14337031', '1612734149.936091'], ['38647.10000', '2.13124321', '1612734158.809939'], ['38646.90000', '0.15000000', '1612734158.757766']]}
[320, {'c': '1395674382', 'b': [['38749.90000', '0.00000000', '1612744547.011538'], ['38706.20000', '0.00208018', '1612742560.538908', 'r']]}, 'book-10', 'XBT/USD']
{'as': [['38750.00000', '5.88008725', '1612744546.720320'],
[320, {'b': [['38669.00000', '0.01600000', '1612758622.979350']], 'c': '3294259068'}, 'book-10', 'XBT/USD']
{'as': [['38680.30000', '0.10000000', '1612758622.813471'],
  [320, {'c': '2458397775', 'a': [['38640.20000', '3.08398805', '1612758718.708876']]}, 'book-10', 'XBT/USD']
  {'as': [['38640.10000', '5.53490762', '1612758718.599895'],
[320, {'b': [['46311.30000', '0.00000000', '1612919210.745633'], ['46303.20000', '0.77181895', '1612919207.986023', 'r']], 'c': '443340964'}, 'book-10', 'XBT/USD']
{'as': [['46355.70000', '5.26799306', '1612919210.675944'],
